// Uncomment the code below and write your tests
import {
  throwError,
  throwCustomError,
  resolveValue,
  MyAwesomeError,
  rejectCustomError,
} from './index';

describe('resolveValue', () => {
  test('should resolve provided value', async () => {
    const data = '15';
    await expect(resolveValue(data)).resolves.toBe(data);
    const value = [15];
    await expect(resolveValue(value)).resolves.toBe(value);
  });
});

describe('throwError', () => {
  test('should throw error with provided message', () => {
    const data = 'Custom error: incorrect path';
    expect(() => throwError(data)).toThrow(data);
  });

  test('should throw error with default message if message is not provided', () => {
    expect(() => throwError()).toThrow('Oops!');
  });
});

describe('throwCustomError', () => {
  test('should throw custom error', () => {
    expect(() => throwCustomError()).toThrow(MyAwesomeError);
  });
});

describe('rejectCustomError', () => {
  test('should reject custom error', async () => {
    await expect(() => rejectCustomError()).rejects.toThrow(MyAwesomeError);
  });
});
